<!-- Converted from the laikago files in pybullet -->
<mujoco model="laikago">
  <compiler angle="radian" />
  <option timestep="0.002">
    <!-- Disable if your dynamics computations are random states. Enable if your dynamics computations will form a full trajectory-->
    <!-- <flag warmstart="disable"/> -->
  </option>
  <size nconmax="100" njmax="500" nkey="1"/>
  <default class="main">
    <geom conaffinity="0" contype="1"/> <!-- default friction, solref, solimp -->
    <!-- <geom conaffinity="0" contype="1" friction="0.4 0.1 0.1" solimp="0 0.8 0.01 0.5 2"/> -->
    <motor ctrllimited="true" ctrlrange="-1 1"/>
  </default>
  <asset>
    <mesh name="torso" file="chassis.stl" />
    <mesh name="hipR" file="hipR.stl" />
    <mesh name="thighR" file="thighR.stl" />
    <mesh name="calf" file="calf.stl" />
    <mesh name="hipL" file="hipL.stl" />
    <mesh name="thighL" file="thighL.stl" />
    <texture builtin="gradient" height="600" rgb1="1 1 1" rgb2="0 0 0" type="skybox" width="100"/>
    <texture builtin="flat" height="762" mark="cross" markrgb="1 1 1" name="texgeom" rgb1="0.8 0.6 0.4" rgb2="0.8 0.6 0.4" type="cube" width="127"/>
    <texture name="texplane" builtin="checker" type="2d" rgb1="1 1 1" rgb2="0.2 0.2 0.8" width="100" height="100"/>
    <material name="MatPlane" shininess="1" specular="1" texrepeat="60 60" texture="texplane"/>
    <material name="geom" texture="texgeom" texuniform="true"/>
  </asset>
  <worldbody>
    <geom conaffinity="1" material="MatPlane" name="floor" rgba="0.8 0.8 0.8 1" size="40 40 40" type="plane"/>
    <light directional="false" diffuse=".2 .2 .2" specular="0 0 0" pos="0 0 5" dir="0 0 -1" castshadow="false"/>
    <light mode="targetbodycom" target="torso" directional="false" diffuse=".8 .8 .8" specular="0.3 0.3 0.3" pos="0 0 4.0" dir="0 0 -1" castshadow="false"/>
    <body name="torso" pos="0 0 0.45" quat="0.5 0.5 0.5 0.5">
      <camera mode="trackcom" name="track" pos="-3 0 0" quat="-0.707388 0 0.706825 0 "/>
      <freejoint name="root"/>
      <geom pos="0 0 0.043794" quat="0.707388 -0.706825 0 0" type="mesh" rgba="1 0.423529 0.0392157 1" mesh="torso"/>
      <body name="FL_hip" pos="0.0817145 0 0.242889">
        <inertial pos="-0.02 0 0" quat="0.629953 0.350191 0.35823 0.593462" mass="1.095" diaginertia="0.000983491 0.000885646 0.000800926" />
        <joint name="FL_hipY" limited="true" range="-0.385 0.385" stiffness="100" damping="10" pos="0 0 0" axis="0 0 1" />
        <geom type="mesh" rgba="1 0.423529 0.0392157 1" mesh="hipL"/>
        <body name="FL_thigh" pos="0.055855 0 0">
          <inertial pos="0 -0.04 -0.04" quat="0.629953 0.350191 0.35823 0.593462" mass="1.527" diaginertia="0.000983491 0.000885646 0.000800926" />
          <joint name="FL_hipX" limited="true" range="-1.2 0.7" stiffness="100" damping="10" pos="0 0 0" axis="1 0 0" />
          <geom type="mesh" rgba="1 0.423529 0.0392157 1" mesh="thighL"/>
          <body name="FL_calf" pos="-0.02069 -0.20833 -0.1422">
            <inertial pos="0 -0.16 -0.02" quat="0.712765 0.000467477 -0.000119366 0.701402" mass="0.241" diaginertia="0.00619655 0.00618196 3.47683e-05" />
            <joint name="FL_knee" springref="-0.7" limited="true" range="-1.57 0.8"  stiffness="100" damping="10" pos="0 0 0" axis="1 0 0" />
            <geom quat="0.707109 0 0.707105 0" type="mesh" rgba="1 0.423529 0.0392157 1" mesh="calf"/>
          </body>
        </body>
      </body>
      <body name="RL_hip" pos="0.0817145 0 -0.194401">
        <inertial pos="-0.02 0 0" quat="0.629953 0.350191 0.35823 0.593462" mass="1.095" diaginertia="0.000983491 0.000885646 0.000800926" />
        <joint name="RL_hipY" limited="true" range="-0.385 0.385" stiffness="100" damping="10" pos="0 0 0" axis="0 0 1" />
        <geom type="mesh" rgba="1 0.423529 0.0392157 1" mesh="hipL"/>
        <body name="RL_thigh" pos="0.055855 0 0">
          <inertial pos="0 -0.04 -0.04" quat="0.629953 0.350191 0.35823 0.593462" mass="1.527" diaginertia="0.000983491 0.000885646 0.000800926" />
          <joint name="RL_hipX" limited="true" range="-0.7 0.7" stiffness="100" damping="10" pos="0 0 0" axis="1 0 0" />
          <geom type="mesh" rgba="1 0.423529 0.0392157 1" mesh="thighL"/>
          <body name="RL_calf" pos="-0.02069 -0.20833 -0.1422">
            <inertial pos="0 -0.16 -0.02" quat="0.712765 0.000467477 -0.000119366 0.701402" mass="0.241" diaginertia="0.00619655 0.00618196 3.47683e-05" />
            <joint name="RL_knee" springref="-0.7"  limited="true" range="-1.57 0.8" stiffness="100" damping="10" pos="0 0 0" axis="1 0 0" />
            <geom quat="0.707109 0 0.707105 0" type="mesh" rgba="1 0.423529 0.0392157 1" mesh="calf"/>
          </body>
        </body>
      </body>
      <body name="FR_hip_motor" pos="-0.0817145 0 0.242889">
        <inertial pos="0.02 0 0" quat="0.629953 0.350191 0.35823 0.593462" mass="1.095" diaginertia="0.000983491 0.000885646 0.000800926" />
        <joint name="FR_hipY" limited="true" range="-0.385 0.385" stiffness="100" damping="10" pos="0 0 0" axis="0 0 -1"/>
        <geom type="mesh" rgba="1 0.423529 0.0392157 1" mesh="hipR"/>
        <body name="FR_thigh" pos="-0.053565 0 0">
          <inertial pos="0 -0.04 -0.04" quat="0.629953 0.350191 0.35823 0.593462" mass="1.527" diaginertia="0.000983491 0.000885646 0.000800926" />
          <joint name="FR_hipX" limited="true" range="-1.2 0.7" stiffness="100" damping="10" pos="0 0 0" axis="1 0 0" />
          <geom type="mesh" rgba="1 0.423529 0.0392157 1" mesh="thighR"/>
          <body name="FR_calf" pos="0.02069 -0.20833 -0.1422">
            <inertial pos="0 -0.16 -0.02" quat="0.712765 0.000467477 -0.000119366 0.701402" mass="0.241" diaginertia="0.00619655 0.00618196 3.47683e-05" />
            <joint name="FR_knee" springref="-0.7" limited="true" range="-1.57 0.8" stiffness="100" damping="10" pos="0 0 0" axis="1 0 0" />
            <geom quat="0.707109 0 0.707105 0" type="mesh" rgba="1 0.423529 0.0392157 1" mesh="calf"/>
          </body>
        </body>
      </body>
      <body name="RR_hip" pos="-0.0817145 0 -0.194401">
        <inertial pos="0.02 0 0" quat="0.629953 0.350191 0.35823 0.593462" mass="1.095" diaginertia="0.000983491 0.000885646 0.000800926" />
        <joint name="RR_hipY" limited="true" range="-0.385 0.385" stiffness="100" damping="10" pos="0 0 0" axis="0 0 -1"/>
        <geom type="mesh" rgba="1 0.423529 0.0392157 1" mesh="hipR"/>
        <body name="RR_thigh" pos="-0.053565 0 0">
          <inertial pos="0 -0.04 -0.04" quat="0.629953 0.350191 0.35823 0.593462" mass="1.527" diaginertia="0.000983491 0.000885646 0.000800926" />
          <joint name="RR_hipX" limited="true" range="-0.7 0.7" stiffness="100" damping="10" pos="0 0 0" axis="1 0 0" />
          <geom type="mesh" rgba="1 0.423529 0.0392157 1" mesh="thighR"/>
          <body name="RR_calf" pos="0.02069 -0.20833 -0.1422">
            <inertial pos="0 -0.16 -0.02" quat="0.712765 0.000467477 -0.000119366 0.701402" mass="0.241" diaginertia="0.00619655 0.00618196 3.47683e-05" />
            <joint name="RR_knee" springref="-0.7" limited="true" range="-1.57 0.8" stiffness="100" damping="10" pos="0 0 0" axis="1 0 0" />
            <geom quat="0.707109 0 0.707105 0" type="mesh" rgba="1 0.423529 0.0392157 1" mesh="calf"/>
          </body>
        </body>
      </body>
    </body>

    <!-- Goal body -->
    <body name="gtorso" pos="1.6 0 0.45" quat="0.5 0.5 0.5 0.5">
      <geom pos="0 0 0.043794" quat="0.707388 -0.706825 0 0" type="mesh" rgba="0 1 0 0.3" contype="0" mesh="torso"/>
      <body name="gFR_hip_motor" pos="-0.0817145 0 0.242889">
        <geom type="mesh" rgba="0 1 0 0.3" contype="0" mesh="hipR"/>
        <body name="gFR_thigh" pos="-0.053565 0 0">
          <geom type="mesh" rgba="0 1 0 0.3" contype="0" mesh="thighR"/>
          <body name="gFR_calf" pos="0.02069 -0.20833 -0.1422">
            <geom quat="0.707109 0 0.707105 0" type="mesh" rgba="0 1 0 0.3" contype="0" mesh="calf"/>
          </body>
        </body>
      </body>
      <body name="gFL_hip" pos="0.0817145 0 0.242889">
        <geom type="mesh" rgba="0 1 0 0.3" contype="0" mesh="hipL"/>
        <body name="gFL_thigh" pos="0.055855 0 0">
          <geom type="mesh" rgba="0 1 0 0.3" contype="0" mesh="thighL"/>
          <body name="gFL_calf" pos="-0.02069 -0.20833 -0.1422">
            <geom quat="0.707109 0 0.707105 0" type="mesh" rgba="0 1 0 0.3" contype="0" mesh="calf"/>
          </body>
        </body>
      </body>
      <body name="gRR_hip" pos="-0.0817145 0 -0.194401">
        <geom type="mesh" rgba="0 1 0 0.3" contype="0" mesh="hipR"/>
        <body name="gRR_thigh" pos="-0.053565 0 0">
          <geom type="mesh" rgba="0 1 0 0.3" contype="0" mesh="thighR"/>
          <body name="gRR_calf" pos="0.02069 -0.20833 -0.1422">
            <geom quat="0.707109 0 0.707105 0" type="mesh" rgba="0 1 0 0.3" contype="0" mesh="calf"/>
          </body>
        </body>
      </body>
      <body name="gRL_hip" pos="0.0817145 0 -0.194401">
        <geom type="mesh" rgba="0 1 0 0.3" contype="0" mesh="hipL"/>
        <body name="gRL_thigh" pos="0.055855 0 0">
          <geom type="mesh" rgba="0 1 0 0.3" contype="0" mesh="thighL"/>
          <body name="gRL_calf" pos="-0.02069 -0.20833 -0.1422">
            <geom quat="0.707109 0 0.707105 0" type="mesh" rgba="0 1 0 0.3" contype="0" mesh="calf"/>
          </body>
        </body>
      </body>
    </body>
    <body name="step0" pos=".8 0 -.5">
      <geom conaffinity="1" pos="0 0 -0.5" rgba=".7 0 0 1" size=".2 1. 0.5" type="box"/>
    </body>
  </worldbody>
  <actuator>
    <motor name="FL_hipY"  gear="20" joint="FL_hipY"/>
    <motor name="FL_hipX"  gear="55" joint="FL_hipX"/>
    <motor name="FL_knee"  gear="55" joint="FL_knee"/>
    <motor name="RL_hipY"  gear="20" joint="RL_hipY"/>
    <motor name="RL_hipX"  gear="55" joint="RL_hipX"/>
    <motor name="RL_knee"  gear="55" joint="RL_knee"/>
    <motor name="FR_hipY"  gear="20" joint="FR_hipY"/>
    <motor name="FR_hipX"  gear="55" joint="FR_hipX"/>
    <motor name="FR_knee"  gear="55" joint="FR_knee"/>
    <motor name="RR_hipY"  gear="20" joint="RR_hipY"/>
    <motor name="RR_hipX"  gear="55" joint="RR_hipX"/>
    <motor name="RR_knee"  gear="55" joint="RR_knee"/>
  </actuator>
  <keyframe>
    <!-- Stable standing position, used when we initialize & reset the gym env -->
    <key qpos='0 0 0.44 0.5 0.5 0.5 0.5 0 0 -0.7 0 0 -0.7 0 0 -0.7 0 0 -0.7'/>
  </keyframe>
</mujoco>
